{"cve_repaire_en": "", "cve_code_exp_url": "", "cve_id": "CVE-2017-14503", "cve_categories": ["category1", "category2"], "cve_code_detect_url": "", "cve_name": "cve_name", "cve_risk_level": "determine", "cve_detail_en": "libarchive 3.3.2 suffers from an out-of-bounds read within lha_read_data_none() in archive_read_support_format_lha.c when extracting a specially crafted lha archive, related to lha_crc16.", "cve_name_en": "cve_name_en", "edit_time": "Sat Oct 12 15:52:51 2019", "cve_code_des_url": "", "cve_other_info": "", "modify_time": "2019-08-15", "cve_detail": "", "references": [{"URL": "https://www.debian.org/security/2018/dsa-4360", "Description": "DEBIAN:DSA-4360"}, {"URL": "https://security.gentoo.org/glsa/201908-11", "Description": "GENTOO:GLSA-201908-11"}, {"URL": "https://bugs.debian.org/875960", "Description": "MISC:https://bugs.debian.org/875960"}, {"URL": "https://github.com/libarchive/libarchive/issues/948", "Description": "MISC:https://github.com/libarchive/libarchive/issues/948"}, {"URL": "https://lists.debian.org/debian-lts-announce/2018/11/msg00037.html", "Description": "MLIST:[debian-lts-announce] 20181129 [SECURITY] [DLA 1600-1] libarchive security update"}, {"URL": "https://access.redhat.com/errata/RHSA-2019:2298", "Description": "REDHAT:RHSA-2019:2298"}, {"URL": "https://usn.ubuntu.com/3736-1/", "Description": "UBUNTU:USN-3736-1"}], "cve_repaire": "", "editor": "warcup", "add_time": "2017-09-17"}